Workbook

Sheet ع1-ن18
B1: =[1]البيانات!D1 -> شركة حصاد الجحاز للتجارة العامة والمقاولات القابضة | J1: =[1]البيانات!B9 -> التوقيع المعتمد | N1: فريق العمل | O1: =[1]البيانات!D9 -> أ مسعود الرفيدي | T1: الوظيفة والتوقيع | U1: =[1]البيانات!N9 -> الشريك المسؤول | AC1: المعيار الدولي | AD1: IFRS | AE1: IAS | AH1: وفقا لمعيار التدقيق الدولي رقم (500) هنالك عدة إجراءات يستخدمها المدقق للحصول على أدلة تدقيق، وهي
B2: =[1]البيانات!D2 -> شركة ذات مسؤولية محدودة | J2: =[1]البيانات!B10 -> المدقق المباشر | O2: =[1]البيانات!D10 -> أ.اسلام الأشقر | U2: =[1]البيانات!N10 -> مدقق حسابات
B3: =[1]البيانات!D3 -> للسنة المالية المنتهية في | J3: =[1]البيانات!B11 -> مدير المراجعة | O3: =[1]البيانات!D11 -> أ. طاهر عبد الغفور | U3: =[1]البيانات!N11 -> مدير المراجعة
B4: =[1]البيانات!D4 -> 45657 | J4: =[1]البيانات!B12 -> الإدارة | O4: =[1]البيانات!D12 -> أ. طاهر عبد الغفور | U4: =[1]البيانات!N12 -> المدير الإداري
A5: المستوي | AF5: كود المرحلة | AG5: مراحل الملف | AH5: الاجراء | AI5: نطاق الإجراء | AJ5: طريقة الاختيار | AK5: امثلة الاستخدام | AN5: اعمال | BE5: نعم=3/لا=1/لا ينطبق=2
B6: فاصل | F6: ورقة عمل رقم | G6: فهرس الملــــــــــــــــــــــــــــــــــــف | AN6: البرنامج | AP6: السكرتارية | AR6: مدير المراجعة | AT6: المدقق الفني | AV6: المدقق حسابات | AX6: وزارة التجارة | AZ6: الهيئة العامة للزكاة والدخل | BB6: الجودة | BC6: الشريك الإداري | BD6: الأرشيف | BE6: نعم=3/لا=1/لا ينطبق=2
B7: 1 | C7: 2 | D7: 3 | E7: 4 | G7: بيان
A8: الأول | B8: ع | C8: ع | D8: ع | E8: ع | F8: ع | G8: ملف عموميات | AB8: نوع الإجابة | AF8: 1
A9: الثاني | B9: =B8 -> ع | C9: ع1 | D9: ع1 | E9: ع1 | F9: ع1 | G9: الملف الدائم (مرحلة استكمال المتطلبات الأساسية | AF9: 1.1 | AH9: الاستفسار | AI9: حقائق معينة
A10: الثالث | B10: =B9 -> ع | C10: =C9 -> ع1 | D10: ع1-1 | E10: ع1-1 | F10: ع1-1 | G10: المستندات من المنشأة | AF10: 1.1.1 | AG10: مرحلة قبول العميل | AH10: الاستفسار | AI10: حقائق معينة | AJ10: 1
A11: الرابع | B11: =B10 -> ع | C11: =C10 -> ع1 | D11: =D10 -> ع1-1 | E11: ع1-1-1 | F11: ع1-1-1 | G11: صورمن المستندات الرسمية الرسمية للمنشأة | AF11: B.16.01 | AG11: مرحلة قبول العميل | AH11: الاستفسار | AI11: حقائق معينة
A12: الخامس | B12: =B11 -> ع | C12: =C11 -> ع1 | D12: =D11 -> ع1-1 | F12: ع1-1-1-1 | G12: السجل التجــــــــــــــــــــــــــــاري وفروع السجل التجاري | AB12: PDF | AF12: B.160101 | AH12: الاستفسار | AI12: حقائق معينة
A13: الخامس | B13: =B12 -> ع | C13: =C12 -> ع1 | D13: =D12 -> ع1-1 | F13: ع1-1-1-2 | G13: عقد تأسيس المنشأة وتعديلاتة وصور من محاضر اجتماعات مجلس الإدارة | AB13: PDF | AF13: B.160102 | AG13: مرحلة قبول العميل | AH13: الاستفسار | AI13: حقائق معينة
A14: الخامس | B14: =B13 -> ع | C14: =C13 -> ع1 | D14: =D13 -> ع1-1 | F14: ع1-1-1-3 | G14: ترخيص المزاولة مختـــــــــــــــــــــــــــــــــــــــــــــــوم | AB14: PDF | AF14: B.160103 | AH14: الاستفسار | AI14: حقائق معينة
A15: الخامس | B15: =B14 -> ع | C15: =C14 -> ع1 | D15: =D14 -> ع1-1 | F15: ع1-1-1-4 | G15: صور هويات الشركاء / صاحب المنشأة | AB15: PDF | AF15: B.160104 | AG15: مرحلة قبول العميل | AH15: الاستفسار | AI15: حقائق معينة
A16: الخامس | B16: =B15 -> ع | C16: =C15 -> ع1 | D16: =D15 -> ع1-1 | F16: ع1-1-1-5 | G16: صورة آخر شهادة زكاة شرعية (شركة / مؤسســـــــة) | AB16: PDF | AF16: B.160105 | AH16: الاستفسار | AI16: حقائق معينة
A17: الخامس | B17: =B16 -> ع | C17: =C16 -> ع1 | D17: =D16 -> ع1-1 | F17: ع1-1-1-6 | G17: شهادة التامينات باجمالى الرواتب قيمة وعــــــــــــــدد | AB17: PDF | AF17: B.160106 | AH17: الاستفسار | AI17: حقائق معينة
A18: الخامس | B18: =B17 -> ع | C18: =C17 -> ع1 | D18: =D17 -> ع1-1 | F18: ع1-1-1-7 | G18: بيان الاستيراد من الجمارك (في حالة وجود استيراد من الخارج) | AB18: PDF | AF18: B.160107 | AH18: الاستفسار | AI18: حقائق معينة
A19: الخامس | B19: =B18 -> ع | C19: =C18 -> ع1 | D19: =D18 -> ع1-1 | F19: ع1-1-1-8 | G19: خلفية عن نشاط المنشأة وفروعـــــــــــــــــــــــــــــــــه | AB19: نموذج/ PDF | AF19: B.160108 | AG19: مرحلة قبول العميل | AH19: الاستفسار | AI19: حقائق معينة
A20: الخامس | B20: =B19 -> ع | C20: =C19 -> ع1 | D20: =D19 -> ع1-1 | F20: ع1-1-1-9 | G20: تفويض برفع القوائم المالية عبر الموقع الالكترونى بوزارة التجارة | AB20: نموذج/ PDF | AF20: B.160109 | AH20: الاستفسار | AI20: حقائق معينة
A21: الخامس | B21: =B20 -> ع | C21: =C20 -> ع1 | D21: =D20 -> ع1-1 | F21: ع1-1-1-10 | G21: خطاب عدم مزاولة النشـــــــــــــــــــــــــــــــــــــــــاط ان كانت لم تمارس النشاط | AB21: نموذج/ PDF | AF21: B.160110 | AH21: الاستفسار | AI21: حقائق معينة
B22: =B21 -> ع | C22: =C21 -> ع1 | D22: =D21 -> ع1-1 | AF22: B.160111 | AH22: الاستفسار | AI22: حقائق معينة
B23: =B22 -> ع | C23: =C22 -> ع1 | D23: =D22 -> ع1-1 | AF23: B.160112 | AH23: الاستفسار | AI23: حقائق معينة
B24: =B23 -> ع | C24: =C23 -> ع1 | D24: =D23 -> ع1-1 | AF24: B.160113 | AH24: الاستفسار | AI24: حقائق معينة
A25: الثاني | B25: =B24 -> ع | C25: ع2 | D25: ع2 | E25: ع2 | F25: ع2 | G25: قوائم الاستبيان والاستقصاء والتقييم والاختبار (المرحلة الاولي لقبول المنشأة والموافقة على الارتباط) | AF25: 1.2 | AG25: مرحلة قبول العميل | AH25: الاستفسار | AI25: حقائق معينة | AJ25: 1
A26: الثالث | B26: =B25 -> ع | C26: =C25 -> ع2 | D26: ع2-1 | E26: ع2-1 | F26: ع2-1 | G26: قوائم استبيان الرقابة الداخلية | AF26: 1.2.1 | AG26: مرحلة تقييم الرقابة الداخلية | AH26: الاستفسار | AI26: حقائق معينة | AJ26: 1
A27: الرابع | B27: =B26 -> ع | C27: =C26 -> ع2 | D27: =D26 -> ع2-1 | E27: ع2-1-1 | F27: ع2-1-1 | G27: تقييم الجهاز التنظيمي والمحاسبة العامة | AB27: نعم=3/لا=1/لا ينطبق=2 | AF27: A7.01 | AH27: الاستفسار | AI27: حقائق معينة
A28: الخامس | B28: =B27 -> ع | C28: =C27 -> ع2 | D28: =D27 -> ع2-1 | E28: =E27 -> ع2-1-1 | F28: ع2-1-1-1 | G28: هل يوجد رسما للهيكل التنظيمي للمنشأة | AB28: 3 | AF28: A.7 | AG28: مرحلة قبول العميل | AH28: الاستفسار | AI28: حقائق معينة
A29: الخامس | B29: =B28 -> ع | C29: =C28 -> ع2 | D29: =D28 -> ع2-1 | E29: =E28 -> ع2-1-1 | F29: ع2-1-1-2 | G29: هل لدى المنشأة لوائح معتمدة بالسياسات والاجراءات المحاسبية | AB29: 3 | AF29: A.7 | AG29: مرحلة قبول العميل | AH29: الاستفسار | AI29: حقائق معينة
A30: الخامس | B30: =B29 -> ع | C30: =C29 -> ع2 | D30: =D29 -> ع2-1 | E30: =E29 -> ع2-1-1 | F30: ع2-1-1-3 | G30: هل يوجد وصف للوظائف ولوائح للقائمين عليها حتى لاتتم الازدواجية في العمل . | AB30: 3 | AF30: A.7 | AH30: الاستفسار | AI30: حقائق معينة
A31: الخامس | B31: =B30 -> ع | C31: =C30 -> ع2 | D31: =D30 -> ع2-1 | E31: =E30 -> ع2-1-1 | F31: ع2-1-1-4 | G31: هل ترفع تقارير دورية للادارة . | AB31: 3 | AF31: A.7 | AH31: الاستفسار | AI31: حقائق معينة
A32: الخامس | B32: =B31 -> ع | C32: =C31 -> ع2 | D32: =D31 -> ع2-1 | E32: =E31 -> ع2-1-1 | F32: ع2-1-1-5 | G32: هل يجري التحري عن المسؤولين عن النقد قبل ترشيحهم ويتم التأمين عليهم ضد سوء الامانة والنقد في الطريق | AB32: 3 | AF32: A.7 | AH32: الاستفسار | AI32: حقائق معينة
A33: الخامس | B33: =B32 -> ع | C33: =C32 -> ع2 | D33: =D32 -> ع2-1 | E33: =E32 -> ع2-1-1 | F33: ع2-1-1-6 | G33: هل من يقوم بتحرير سندات الصرف اشخاص غير امين الخزينة . | AB33: 3 | AF33: A.7 | AH33: الاستفسار | AI33: حقائق معينة
A34: الخامس | B34: =B33 -> ع | C34: =C33 -> ع2 | D34: =D33 -> ع2-1 | E34: =E33 -> ع2-1-1 | F34: ع2-1-1-7 | G34: هل يتم حفظ دفاتر الشيكات والدفاتر المحاسبية في مكان امن . | AB34: 3 | AF34: A.7 | AH34: الاستفسار | AI34: حقائق معينة
A35: الخامس | B35: =B34 -> ع | C35: =C34 -> ع2 | D35: =D34 -> ع2-1 | E35: =E34 -> ع2-1-1 | F35: ع2-1-1-8 | G35: هل يوجد شخص يقوم بمراجعة قيود التسوية غير الشخص الذي يقوم باعدادها . | AB35: 3 | AF35: A.7 | AH35: الاستفسار | AI35: حقائق معينة
B36: =B35 -> ع | C36: =C35 -> ع2 | D36: =D35 -> ع2-1 | E36: =E35 -> ع2-1-1 | AF36: A.7 | AH36: الاستفسار | AI36: حقائق معينة
A37: الرابع | B37: =B36 -> ع | C37: =C36 -> ع2 | D37: =D36 -> ع2-1 | E37: ع2-1-2 | F37: ع2-1-2 | G37: الرقابة الداخلية على إدارة المقبوضات والمدفوعات | AB37: نعم=3/لا=1/لا ينطبق=2 | AF37: A.7.02 | AG37: مرحلة تقييم الرقابة الداخلية | AH37: الاستفسار | AI37: حقائق معينة
A38: الخامس | B38: =B37 -> ع | C38: =C37 -> ع2 | D38: =D37 -> ع2-1 | E38: =E37 -> ع2-1-2 | F38: ع2-1-2-1 | G38: هل يتم تدريب امناء الصندوق والعهد | AB38: 3 | AF38: A.7 | AH38: الاستفسار | AI38: حقائق معينة
A39: الخامس | B39: =B38 -> ع | C39: =C38 -> ع2 | D39: =D38 -> ع2-1 | E39: =E38 -> ع2-1-2 | F39: ع2-1-2-2 | G39: هل سندات الصرف والقبض مرقمة ويتم مراجعة التسلسل | AB39: 3 | AF39: A.7 | AH39: الاستفسار | AI39: حقائق معينة
A40: الخامس | B40: =B39 -> ع | C40: =C39 -> ع2 | D40: =D39 -> ع2-1 | E40: =E39 -> ع2-1-2 | F40: ع2-1-2-3 | G40: هل يتم مراجعة مرفقات سندات الصرف والقبض قبل اعتمادها | AB40: 3 | AF40: A.7 | AH40: الاستفسار | AI40: حقائق معينة
...

Sheet Sheet6

Sheet Sheet2
A1: المستوى | B1: فاصل | C1: 1 | D1: 2 | E1: 3 | F1: 4 | G1: 5 | H1: بيان
A2: 0 | D2: الرجاء كتابة الدليل المرفق هنا | E2: فاصل | I2: ورقة عمل رقم | J2: فهرس الملــــــــــــــــــــــــــــــــــــف
A3: 0 | E3: 1 | F3: 2 | G3: 3 | H3: 4 | J3: بيان
A4: 1 | B4: ع | C4: ع | D4: ع | E4: ع | F4: ع | G4: ملف عموميات
A5: 2 | B5: ع | C5: ع1 | D5: ع1 | E5: ع1 | F5: ع1 | G5: الملف الدائم (مرحلة استكمال المتطلبات الأساسية
A6: 3 | B6: ع | C6: ع1 | D6: ع1-1 | E6: ع1-1 | F6: ع1-1 | G6: المستندات من المنشأة
A7: 4 | B7: ع | C7: ع1 | D7: ع1-1 | E7: ع1-1-1 | F7: ع1-1-1 | G7: صورمن المستندات الرسمية الرسمية للمنشأة
A8: 5 | B8: ع | C8: ع1 | D8: ع1-1 | F8: ع1-1-1-1 | G8: السجل التجــــــــــــــــــــــــــــاري وفروع السجل التجاري
A9: 5 | B9: ع | C9: ع1 | D9: ع1-1 | F9: ع1-1-1-2 | G9: عقد تأسيس المنشأة وتعديلاتة وصور من محاضر اجتماعات مجلس الإدارة
A10: 5 | B10: ع | C10: ع1 | D10: ع1-1 | F10: ع1-1-1-3 | G10: ترخيص المزاولة مختـــــــــــــــــــــــــــــــــــــــــــــــوم
A11: 5 | B11: ع | C11: ع1 | D11: ع1-1 | F11: ع1-1-1-4 | G11: صور هويات الشركاء / صاحب المنشأة
A12: 5 | B12: ع | C12: ع1 | D12: ع1-1 | F12: ع1-1-1-5 | G12: صورة آخر شهادة زكاة شرعية (شركة / مؤسســـــــة)
A13: 5 | B13: ع | C13: ع1 | D13: ع1-1 | F13: ع1-1-1-6 | G13: شهادة التامينات باجمالى الرواتب قيمة وعــــــــــــــدد
A14: 5 | B14: ع | C14: ع1 | D14: ع1-1 | F14: ع1-1-1-7 | G14: بيان الاستيراد من الجمارك (في حالة وجود استيراد من الخارج)
A15: 5 | B15: ع | C15: ع1 | D15: ع1-1 | F15: ع1-1-1-8 | G15: خلفية عن نشاط المنشأة وفروعـــــــــــــــــــــــــــــــــه
A16: 5 | B16: ع | C16: ع1 | D16: ع1-1 | F16: ع1-1-1-9 | G16: تفويض برفع القوائم المالية عبر الموقع الالكترونى بوزارة التجارة
A17: 5 | B17: ع | C17: ع1 | D17: ع1-1 | F17: ع1-1-1-10 | G17: خطاب عدم مزاولة النشـــــــــــــــــــــــــــــــــــــــــاط ان كانت لم تمارس النشاط
A18: 3 | B18: ع | C18: ع1 | D18: ع1-1
A19: 3 | B19: ع | C19: ع1 | D19: ع1-1
A20: 3 | B20: ع | C20: ع1 | D20: ع1-1
A21: 2 | B21: ع | C21: ع2 | D21: ع2 | E21: ع2 | F21: ع2 | G21: قوائم الاستبيان والاستقصاء والتقييم والاختبار (المرحلة الاولي لقبول المنشأة والموافقة على الارتباط)
A22: 3 | B22: ع | C22: ع2 | D22: ع2-1 | E22: ع2-1 | F22: ع2-1 | G22: قوائم استبيان الرقابة الداخلية
A23: 4 | B23: ع | C23: ع2 | D23: ع2-1 | E23: ع2-1-1 | F23: ع2-1-1 | G23: تقييم الجهاز التنظيمي والمحاسبة العامة
A24: 5 | B24: ع | C24: ع2 | D24: ع2-1 | E24: ع2-1-1 | F24: ع2-1-1-1 | G24: هل يوجد رسما للهيكل التنظيمي للمنشأة
A25: 5 | B25: ع | C25: ع2 | D25: ع2-1 | E25: ع2-1-1 | F25: ع2-1-1-2 | G25: هل لدى المنشأة لوائح معتمدة بالسياسات والاجراءات المحاسبية
A26: 5 | B26: ع | C26: ع2 | D26: ع2-1 | E26: ع2-1-1 | F26: ع2-1-1-3 | G26: هل يوجد وصف للوظائف ولوائح للقائمين عليها حتى لاتتم الازدواجية في العمل .
A27: 5 | B27: ع | C27: ع2 | D27: ع2-1 | E27: ع2-1-1 | F27: ع2-1-1-4 | G27: هل ترفع تقارير دورية للادارة .
A28: 5 | B28: ع | C28: ع2 | D28: ع2-1 | E28: ع2-1-1 | F28: ع2-1-1-5 | G28: هل يجري التحري عن المسؤولين عن النقد قبل ترشيحهم ويتم التأمين عليهم ضد سوء الامانة والنقد في الطريق
A29: 5 | B29: ع | C29: ع2 | D29: ع2-1 | E29: ع2-1-1 | F29: ع2-1-1-6 | G29: هل من يقوم بتحرير سندات الصرف اشخاص غير امين الخزينة .
A30: 5 | B30: ع | C30: ع2 | D30: ع2-1 | E30: ع2-1-1 | F30: ع2-1-1-7 | G30: هل يتم حفظ دفاتر الشيكات والدفاتر المحاسبية في مكان امن .
A31: 5 | B31: ع | C31: ع2 | D31: ع2-1 | E31: ع2-1-1 | F31: ع2-1-1-8 | G31: هل يوجد شخص يقوم بمراجعة قيود التسوية غير الشخص الذي يقوم باعدادها .
A32: 4 | B32: ع | C32: ع2 | D32: ع2-1 | E32: ع2-1-1
A33: 4 | B33: ع | C33: ع2 | D33: ع2-1 | E33: ع2-1-2 | F33: ع2-1-2 | G33: الرقابة الداخلية على إدارة المقبوضات والمدفوعات
A34: 5 | B34: ع | C34: ع2 | D34: ع2-1 | E34: ع2-1-2 | F34: ع2-1-2-1 | G34: هل يتم تدريب امناء الصندوق والعهد
A35: 5 | B35: ع | C35: ع2 | D35: ع2-1 | E35: ع2-1-2 | F35: ع2-1-2-2 | G35: هل سندات الصرف والقبض مرقمة ويتم مراجعة التسلسل
A36: 5 | B36: ع | C36: ع2 | D36: ع2-1 | E36: ع2-1-2 | F36: ع2-1-2-3 | G36: هل يتم مراجعة مرفقات سندات الصرف والقبض قبل اعتمادها
A37: 5 | B37: ع | C37: ع2 | D37: ع2-1 | E37: ع2-1-2 | F37: ع2-1-2-4 | G37: هل يتم التحقق من المستلم قبل تسليمه الشيكات او النقدية
A38: 4 | B38: ع | C38: ع2 | D38: ع2-1 | E38: ع2-1-2
A39: 4 | B39: ع | C39: ع2 | D39: ع2-1 | E39: ع2-1-3 | F39: ع2-1-3 | G39: النقدية بالصندوق
A40: 5 | B40: ع | C40: ع2 | D40: ع2-1 | E40: ع2-1-3 | F40: ع2-1-3-1 | G40: هل يتم الفصل بين معتمد الصرف وامين الخزينة والقائم بتسجيل الصرف
...

Sheet برنامج الملاك
A1: الأول | M1: وظائف مالك النظام 1
A2: الثاني | M2: 1.1 ادارة الملف الشخصي
B3: اسم التابة | C3: السمات / الوصف | D3: البيانات المدخلة | E3: نوع البيانات المدخلة | F3: البيانات المخرجة | G3: شرط ملء البيان | H3: الوثائق المرفوعة | I3: التحقق والتوثيق | J3: المهام | K3: ملاحظات | L3: ملاحظات إضافية
A4: * | C4: وظيفة تسجيل دخول أدمن ملاك البرنامج | D4: يجب ان يسمح النظام لآدمن الملاك بتسجيل الدخول بشكل آمن باستخدام البريد الالكتروني وكلمة المرور | L4: اول مرة كيف يفتح برنامج الملاك هل سيتم إضافة الايميلات وأرقام الجولات في كود البرنامج ام سيتم إعطاء فرصة عند الدخول اول مرة بكتابة الايميل والرقم السري
A5: الرابع | B5: تسجيل الدخول | C5: دخول المستخدمين الملاك / والمطور / وموظفين الدعم الفني للمطور وموظفين الدعم المهني للمدقق ملاك البرنامج | D5: اسم المستخدم | E5: TEXT | F5: يتم السماح بالدخول علي الموقع | H5: لا يوجد | I5: تسجيل دخول بتحقق ثنائي
A6: الرابع | D6: كلمة المرور | E6: TEXT | K6: في حال تم نسيان او فقدان كلمة المرور يتم إعادة ارسالها مرة اخري في الايميل الخاص بملاك الشركة
A7: الرابع | D7: نسيت كلمة المرور | E7: TEXT + number | K7: مجرد قبول الدخول يتم الانتقال الي واجهة المشترك
A8: الرابع
A9: الثاني | M9: 1.2 اعدادات النظام
A10: الثالث | M10: 1.1.1 وظيفة تسجيل دخول الادمن
A11: * | C11: اعدادات برنامج الملاك (النظام) | D11: يجب ان يتيح نظام المشرف إمكانية تكوين وإدارة إعدادات نظاق النظام وتشمل هذه الاعدادات بيانات يتم قراءتها واختيارها من قائمة منسدلة عند إضافة مشترك
A12: الرابع | B12: إعدادات النظام | C12: اعدادات أساسية لنافذة ملاك البرنامج | D12: قائمة بلاد العالم | E12: قائمة من مواقع الكترونية | F12: كل بلد علي حدة | H12: لا يوجد وثائق مرفقة | I12: لا يوجد تحقق مطلوب | L12: هل سيتم تحديد الدول والمدن والمناطق داخل كود البرنامج حتي يتم قرأئتها اثناء إضافة مشترك ام سيكون هناك إعدادات والأفضل الاولي | M12: فيما يتعلق باعدادات البلد والمدينة والمنطقة والمواقع الوزارية وفي برنامج المشتركين لا يوجد حوجة لوضعها في اعدادات برنامج الملاك لان استعمالها عمليا يكون عند إضافة مشترك وكل مشترك لة بلدة الخاص لذلك اقترح ان تكون في الكود وليس في النوافذ وعند إضافة مشترك توجد الخانة كقائمة منسدلة يتم التحديد ديناميكيا
A13: الرابع | D13: قائمة بمدن العالم | E13: قائمة من مواقع الكترونية | F13: كل مدينة خاصة بالبلد المحددة أعلاه
A14: الرابع | D14: قائمة بمناطق العالم | E14: قائمة من مواقع الكترونية | F14: المناطق المرتبطة بالمدن أعلاه
A15: الرابع | D15: موقع هيئة المحاسبين القانونيين | E15: قائمة من مواقع الكترونية | F15: مواقع الهيئة المرتبطة بالبلد والمدينة أعلاه | K15: يتحدد ليتم اختيارة عند ادخال بيانات المشترك
A16: الرابع | D16: موقع وزارة التجارة | E16: قائمة من مواقع الكترونية | F16: مواقع وزارة التجارة المرتبطة بالبلد أعلاه
A17: الرابع | D17: موقع مصلحة الضرائب والزكاة | E17: قائمة من مواقع الكترونية | F17: مواقع هيئة الزكاة والدخل المرتبطة بالبلد أعلاه
A18: الرابع | D18: مستخدمين الدعم الفني | E18: يتم الإضافة في اعدادات البرنامج | H18: عقد الدعم الفني | I18: لا يوجد تحقق مطلوب | M18: يجب إضافة المستخدمين وعلي أسس علمية وضوابط وهذا للملاك والشركة الدعم الفني ومستخدمين الدعم المهني
A19: الرابع | D19: مستخدمين الدعم المهني | E19: يتم الإضافة في اعدادات البرنامج | H19: عقد الدعم المهني
A20: الرابع | D20: مستخدمين الملاك | E20: يتم الإضافة في اعدادات البرنامج | H20: عقد تأسيس الشركة
A21: الرابع | D21: أنواع الاشتراك | E21: مراجع قانوني / مكتب استشاري / فرد
A22: الثاني | M22: 1.3 إدارة لوحة تحكم المشتركين
A23: الثالث | M23: 1.2.1 إضافة مشترك
A24: * | B24: إضافة مشترك | C24: إضافة مشترك | D24: يجب ان يتيح النظام للمسؤول للمسؤول " احد الملاك " إمكانية إضافة مشترك جديد مع ادخال البيانات الأساسية الكاملة للمشترك والمعلومات القانونية والمالية والتقنية | L24: البيانات المظللة بالتنقيط من نفس اللون يعني التظليل ان تلك البيانات ستنتقل الي نافذة الURLللمشترك ولا يمكن التعديل عليها فقط في نافذة الURL (نافذة المشترك) وتكون للاطلاع فقط وتعديلها يلزم الرجوع الي المالك علي ان يكون نفس التنقيط بيانات يمكن تعديلها في نافذة المشترك
A25: الرابع | C25: معلومات الموقع بيانات الزامية | D25: البلد | E25: TEXT | F25: البلد التي يتم اختيارها | G25: شرط أساسي | H25: العنوان الوطني | I25: لا يوجد تحقق مطلوب | K25: عند تحديد البلد في واجهة إضافة المشترك يجب ان تكون ديناميكية بحيث علي أساس البلد تنحصر المعلومات عند إضافة المشترك بحيث يتم الاختيار من مدن هذه البلد
A26: الرابع | D26: المدينة | E26: TEXT | F26: المدينة التي تم اختيارها | G26: شرط أساسي | H26: العنوان الوطني | I26: لا يوجد تحقق مطلوب | K26: وهكذا عند تحديد المدينة تتلخص القائمة المنسدلة في مناطق تلك المدينة
A27: الرابع | D27: المنطقة | E27: TEXT | F27: المنطقة التي تم اختيارها | G27: شرط أساسي | H27: العنوان الوطني | I27: لايود تحقق مطلوب | K27: وهكذا عند تحديد المنطقة تتلخص القائمة المنسدلة في مناطق تلك المدينة
A28: الرابع | C28: معلومات الترخيص بيانات الزامية | D28: نوع الترخيص | E28: Number | F28: النوع الذي تم اختيارة | G28: شرط أساسي | H28: شهادة الترخيص | I28: يتم التحقق من موقع الهيئة
A29: الرابع | D29: رقم الترخيص | E29: Number | F29: الرقم الذي يتم كتابتة | G29: شرط أساسي
A30: الرابع | D30: تاريخ الترخيص | E30: DATE | F30: التاريخ الذي يتم كتابتة | G30: شرط أساسي | K30: يتوفر الميلادي والهجري
A31: الرابع | D31: اسم الترخيص | E31: TEXT | F31: الاسم حسب ما موضح بالترخيص | G31: شرط أساسي | K31: قد يكون اسم الترخيص طويلا او معقدا لذلك يجب ان تكون هناك آلية لاختيار اسم محدد كاسم العائلة او الاسم التجاري مثال (مكتب مسعود الرفيدي محاسبون ومراجعون قانونيون واستشاريون يمكن اختصارها في اسم الURL الي الرفيدي فقط
A32: الرابع | C32: معلومات الكيان القانوني الزامي | D32: الكيان القانوني للمنشأة | E32: TEXT | F32: شرط | G32: شرط أساسي | H32: عقد التاسيس ان وجد في حالة الشركات و السجل التجاري | I32: يتم التحقق من موقع وزارة التجارة | K32: يتم الاختيار من قائمة منسدلة الكيان القانوني حسب الدولة (شركة/ مؤسسة/الخخخخ)
A33: الرابع | D33: نوع الكيان القانوني | E33: TEXT | F33: شرط | G33: شرط أساسي | K33: يتم الاختيار من قائمة منسدلة نوع الكيان القانوني فردية / شخص واحد / ذات مسؤولية محدودة/ مساهمة عامة / تضامنية / الخخخخخخ
A34: الرابع | D34: جنسية الكيان القانوني | E34: TEXT | F34: شرط | G34: شرط أساسي | K34: يتم الاختيار من قائمة منسدلة ( البلد المحدد أعلاه / مختلطة / اجنبية )
A35: الرابع | D35: اسم صاحب صاحب / أصحاب المنشأة | E35: TEXT | F35: شرط | G35: شرط أساسي
A36: الرابع | D36: رقم السجل التجاري | E36: Number | F36: شرط | G36: شرط أساسي | K36: مثال 1010515969
A37: الرابع | D37: الرقم الضريبي | E37: Number | F37: شرط | G37: شرط أساسي | H37: شهادة التسجيل في القيمة المضافة | I37: يتم التحقق من موقع الزكاة والدخل
A38: الرابع | D38: الرقم الموحد | E38: Number | F38: شرط | G38: شرط أساسي | H38: شهادة الرقم الموحد | K38: 700123456مثال
A39: الرابع | D39: نشاط السجل التجاري | E39: TEXT | F39: شرط | G39: شرط أساسي | H39: ملخص نشاط السجل االتجاي
A40: الرابع | D40: تاريخ السجل التجاري | E40: DATE | F40: شرط | G40: شرط أساسي | H40: لا يوجد | I40: يتم التحقق من موقع وزارة التجارة | K40: يتوفر الميلادي والهجري
...

Sheet برنامج المشترك
A1: الأول | T1: وظائف مالك النظام 1
A2: الثاني | K2: https://www.google.com/ | T2: 1.1 ادارة الملف الشخصي
B3: اسم التابة | C3: السمات / الوصف | D3: البيانات المدخلة | E3: نوع البيانات المدخلة | F3: البيانات المخرجة | G3: شرط ملء البيان | H3: الوثائق المرفوعة | I3: التحقق والتوثيق | J3: المهام | K3: ملاحظات | L3: ملاحظات إضافية
A4: * | C4: وظيفة تسجيل دخول أدمن المشتركين البرنامج | D4: يجب ان يسمح النظام لآدمن المشتركين بتسجيل الدخول بشكل آمن باستخدام البريد الالكتروني وكلمة المرور بعد انشاء الURL الخاص بالمشترك
A5: الرابع | B5: تسجيل الدخول | C5: دخول المستخدمين المشتركين | D5: اسم المستخدم | E5: TEXT | F5: يتم السماح بالدخول علي الموقع | H5: لا يوجد | I5: تسجيل دخول بتحقق ثنائي | J5: ادمن المشتركين
A6: الرابع | D6: كلمة المرور | E6: TEXT | J6: ادمن المشتركين | K6: في حال تم نسيان او فقدان كلمة المرور يتم إعادة ارسالها مرة اخري في الايميل الخاص بالمشتركين الشركة
A7: الرابع | D7: نسيت كلمة المرور | E7: TEXT + number | J7: ادمن المشتركين | K7: مجرد قبول الدخول يتم الانتقال الي واجهة المشترك
A8: الرابع | B8: اول مرة يتم دخول في الURL بواسطة الادمن المعين عند تسجيل الاشنراك وذلك اول تغيير كلمة المرور التي أرسلت لة ثم عمل الاعدادات للبرنامج كما موضح ادناه علما بان تغيير كلمة المرور تكون من نافذة اعدادات المستخدمين وليس نافذة لحالة
A9: الثاني | T9: 1.2 اعدادات النظام
A10: الثالث | T10: 1.1.1 وظيفة تسجيل دخول الادمن
D11: يجب ان يتيح النظام للادمن إمكانية تكوين وإدارة إعدادات البرنامج والمتمثلة في
B12: اعــــــــــــــــــــــــــــــــــــــــــــــــــــــــــــــــــــــــــــــــــــــــــــــــــــــــــــــــدادات النـــــــــــــــــــــــــــــــــــــــــــــــــــــــــــــــــــــــــــــــــــــــــــــــــــــــــظام | C12: اعدادات أساسية لنافذة المشتركين البرنامج | K12: بيانات منقولة من نافذة ملاك البرنامج وخاصة بهذا المشترك ويمكن التعديل علي بعض البيانات والمحددة بالتنقيط باللون الأحمر في الخلية في نسخة المشترك وباقي البيانات بدون تنقيط لا يمكن تعديلها ولا تاثر علي باقي المشتركين
C13: معلومات الموقع | D13: البلد | E13: منقول من نافذة الملاك | F13: منقول من نافذة الملاك | G13: منقول من نافذة الملاك ويمكن التعديل | H13: لا يوجد وثائق مرفوعة | I13: لا يوجد وثائق مرفوعة
D14: المدينة | E14: منقول من نافذة الملاك | F14: منقول من نافذة الملاك | G14: منقول من نافذة الملاك ويمكن التعديل | H14: لا يوجد وثائق مرفوعة | I14: لا يوجد وثائق مرفوعة
D15: المنطقة | E15: منقول من نافذة الملاك | F15: منقول من نافذة الملاك | G15: منقول من نافذة الملاك ويمكن التعديل | H15: لا يوجد وثائق مرفوعة | I15: لا يوجد وثائق مرفوعة
D16: نوع الترخيص | E16: منقول من نافذة الملاك | F16: منقول من نافذة الملاك | G16: منقول من نافذة الملاك ويمكن التعديل | H16: لا يوجد وثائق مرفوعة | I16: لا يوجد وثائق مرفوعة
D17: رقم الترخيص | E17: منقول من نافذة الملاك | F17: منقول من نافذة الملاك | G17: منقول من نافذة الملاك ويمكن التعديل | H17: لا يوجد وثائق مرفوعة | I17: لا يوجد وثائق مرفوعة
D18: تاريخ الترخيص | E18: منقول من نافذة الملاك | F18: منقول من نافذة الملاك | G18: منقول من نافذة الملاك ويمكن التعديل | H18: لا يوجد وثائق مرفوعة | I18: لا يوجد وثائق مرفوعة
D19: اسم المرخص لة | E19: منقول من نافذة الملاك | F19: منقول من نافذة الملاك | G19: منقول من نافذة الملاك ويمكن التعديل | H19: لا يوجد وثائق مرفوعة | I19: لا يوجد وثائق مرفوعة
A20: الرابع | D20: موقع هيئة المحاسبين القانونيين | E20: قائمة من مواقع الكترونية | F20: مواقع الهيئة المرتبطة بالبلد والمدينة أعلاه | G20: منقول من نافذة الملاك ويمكن التعديل | H20: لا يوجد وثائق مرفوعة | I20: لا يوجد وثائق مرفوعة | J20: ادمن المشتركين
A21: الرابع | D21: موقع وزارة التجارة | E21: قائمة من مواقع الكترونية | F21: مواقع وزارة التجارة المرتبطة بالبلد أعلاه | G21: منقول من نافذة الملاك ويمكن التعديل | J21: ادمن المشتركين
A22: الرابع | D22: موقع مصلحة الضرائب والزكاة | E22: قائمة من مواقع الكترونية | F22: مواقع هيئة الزكاة والدخل المرتبطة بالبلد أعلاه | G22: منقول من نافذة الملاك ويمكن التعديل | J22: ادمن المشتركين
A23: الرابع | D23: مستخدمين برنامج المشتركين | E23: حسب صفحة المستخدمين المرفقة يتم تعبئتها | F23: يجب تحديد المسؤوليات والمسميات الوظيفية | G23: يتم ادخالة حسب نافذة تضمن تووزيع الصلاحيات | H23: بيانات الموظفين | I23: التحقق بارسال رسائل التأكيد للجوالات | J23: ادمن المشتركين | T23: اضافة مستخدمين المشترك يكون من خلال نافذة متخصصة فيها يمكن تحديد الصلاحيات / الفرع التابع لة المستخدم / المهام التي يتم تحديدها في دليل المراجعة
A24: الرابع
A25: الرابع | C25: دليل الحسابات | D25: دليل شجري مفتوح المستوي ويمكن التعديل علية | E25: منقول من برنامج الملاك | F25: منقول من برنامج الملاك | G25: منقول من نافذة الملاك ويمكن التعديل | H25: دليل الحسابات | J25: ادمن المشتركين | K25: الأدلة التي يعمل بها البرنامج وتنقل بآخر صورة تم اعدادها في برنامج الملاك مع الURL الخاص بالمشترك والبيانات الأخرى المنقولة وبعد انتقالها الي الURL الخاص بالمشترك تنفصل عن نسخة ملاك البرنامج ولا يوجد أي ارتباط بينهما لذلك يستطيع المشترك ان يغير في تلك البيانات دون التاثير علي نسخة ملاك البرنامج او المشتركين الآخرين
A26: الرابع | C26: دليل المراجعة | D26: دليل شجري مفتوح المستوي ويمكن التعديل علية | E26: منقول من برنامج الملاك | F26: منقول من برنامج الملاك | G26: منقول من نافذة الملاك ويمكن التعديل | H26: دليل المراجعة | J26: ادمن المشتركين
A27: الرابع | C27: دليل الإجراءات | D27: دليل شجري مفتوح المستوي ويمكن التعديل علية | E27: منقول من برنامج الملاك | F27: منقول من برنامج الملاك | G27: منقول من نافذة الملاك ويمكن التعديل | H27: دليل الإجراءات | J27: ادمن المشتركين
C28: فهرس علامات المراجعة | D28: قائمة بالعلامات المستخدة تظهر في أوراق العمل كقائمة منسدلة يقوم المدقق الفني ومساعدية ومدير التدق باستعمالها | E28: اختيار من قائمة منسدلة | F28: العلامة المختارة في مكان ظاهر بورقة العمل | G28: اختياري ويدل علي انة تم فحص البند
A29: * | C29: اعدادات برنامج المشتركين (النظام) | D29: يجب ان يتيح النظام للادمن إمكانية تكوين وإدارة إعدادات البرنامج والمتمثلة في
A30: الرابع | C30: بيانات الاشتراك | J30: ادمن المشتركين | K30: بيانات منقولة من نافذة ملاك البرنامج وخاصة فقط بهذا المشترك وهي ثابتة لا يمكن تعديلها الا بالرجوع لملاك البرنامج لضمان وحدة معلومات المشترك الواحد
A31: الرابع | C31: معلومات الموقع بيانات الزامية | D31: البلد | E31: TEXT | F31: منقول من نافذة الملاك | G31: لا يوجد تعبئة بيانات | H31: العنوان الوطني | I31: يتم التحقق من بيانات العنوان الوطني | J31: ادمن المشتركين
A32: الرابع | D32: المدينة | E32: TEXT | F32: منقول من نافذة الملاك | G32: لا يوجد تعبئة بيانات | J32: ادمن المشتركين
A33: الرابع | D33: المنطقة | E33: TEXT | F33: منقول من نافذة الملاك | G33: لا يوجد تعبئة بيانات | J33: ادمن المشتركين
A34: الرابع | C34: معلومات الترخيص بيانات الزامية | D34: نوع الترخيص | E34: Number | F34: منقول من نافذة الملاك | G34: لا يوجد تعبئة بيانات | H34: شهادة الترخيص | I34: يتم التحقق من موقع الهيئة | J34: ادمن المشتركين
A35: الرابع | D35: رقم الترخيص | E35: Number | F35: منقول من نافذة الملاك | G35: لا يوجد تعبئة بيانات | J35: ادمن المشتركين
A36: الرابع | D36: تاريخ الترخيص | E36: DATE | F36: منقول من نافذة الملاك | G36: لا يوجد تعبئة بيانات | J36: ادمن المشتركين
A37: الرابع | D37: اسم الترخيص | E37: TEXT | F37: منقول من نافذة الملاك | G37: لا يوجد تعبئة بيانات | J37: ادمن المشتركين
A38: الرابع | C38: اعدادات أساسية لنافذة المشترك بالبرنامج | D38: =-9876 -> -9876 | E38: قائمة من مواقع الكترونية | F38: مواقع الهيئة المرتبطة بالبلد والمدينة أعلاه | G38: منقول من نافذة الملاك ويمكن التعديل | H38: لا يوجد وثائق مرفوعة | I38: لا يوجد وثائق مرفوعة | J38: ادمن المشتركين | K38: بيانات منقولة من نافذة ملاك البرنامج وخاصة بهذا المشترك ويمكن التعديل عليها في نسخة المشترك ولا تاثر علي باقي المشتركين
A39: الرابع | D39: موقع وزارة التجارة | E39: قائمة من مواقع الكترونية | F39: مواقع وزارة التجارة المرتبطة بالبلد أعلاه | G39: منقول من نافذة الملاك ويمكن التعديل | J39: ادمن المشتركين
A40: الرابع | D40: موقع مصلحة الضرائب والزكاة | E40: قائمة من مواقع الكترونية | F40: مواقع هيئة الزكاة والدخل المرتبطة بالبلد أعلاه | G40: منقول من نافذة الملاك ويمكن التعديل | J40: ادمن المشتركين
...

Sheet دليل الحسابات
A1: المستوى | B1: رقم الحساب | C1: اسم الحساب | D1: التعريف المحاسبي | E1: السياسات المحاسبية | F1: IFRS | G1: IAS | H1: المعايير المحلية (SOCPA) | I1: معايير المراجعة (ISA) | J1: إجراءات المراجعة | K1: اللوائح والنُظم (السعودية) | L1: ملاحظات الإفصاح | O1: رمز الهدف | V1: الأهداف المرتبطة
A2: المستوى الأول | B2: 1 | C2: الموجودات | D2: موارد خاضعة لسيطرة المنشأة ينتج عنها منافع اقتصادية مستقبلية | E2: تصنيف متداول وغير متداول | F2: — | G2: IAS 1 | H2: إطار العرض العام SOCPA | I2: ISA 315 / 330 | J2: مراجعة هيكلية فقط دون أرصدة | K2: نظام الشركات السعودي | L2: لا توجد إفصاحات منفصلة | O2: E,C,R,V,P | Q2: E | R2: C | S2: R | T2: V | U2: P | V2: (خارجي) جميع أهداف المراجعة / (داخلي) حماية الأصول – سلامة التصنيف – دقة القياس
A3: المستوى الثاني | B3: 11 | C3: الموجودات المتداولة | D3: أصول يتوقع بيعها أو استخدامها خلال 12 شهر | E3: قياس بالتكلفة أو صافي القيمة القابلة للتحقق | F3: — | G3: IAS 1 / IAS 2 | H3: إطار العرض العام SOCPA | I3: ISA 315 / 330 | J3: مطابقة دورية وتحليل دورة التشغيل | K3: زكاة القيمة المضافة | L3: الإفصاح عن السياسات التصنيفية | O3: E,V,P | V3: (خارجي) Existence – Valuation – Presentation / (داخلي) حماية الأصول المتداولة – دقة التصنيف – المطابقة الدورية
A4: المستوى الثالث | B4: 1101 | C4: النقد وما في حكمه | D4: أرصدة نقدية ومعادلات نقدية عالية السيولة تستحق خلال 3 أشهر | E4: إثبات بالقيمة الاسمية، ضوابط جرد وصرف | F4: IFRS 7 | G4: IAS 7 | H4: SOCPA للتقارير النقدية | I4: ISA 240 / 505 | J4: مطابقة كشوف البنك، جرد مفاجئ للصندوق | K4: تعليمات البنك المركزي السعودي | L4: الإفصاح عن الأرصدة المقيدة | O4: E,V,C | V4: (خارجي) Existence – Valuation – Completeness / (داخلي) حماية النقدية – الرقابة على العهد – دقة الجرد والتسوية
A5: المستوى الرابع | B5: 1101001 | C5: صندوق رئيسي | D5: نقدية فعلية بالمنشأة | E5: حدود عهدة، جرد مفاجئ، فصل العهد الشخصية | F5: IFRS 7 | G5: IAS 7 | H5: سياسات SOCPA للنقدية | I5: ISA 240 / 505 | J5: فحص سندات الصرف، عد فعلي، مطابقة الرصيد | K5: لائحة الصرف النقدي | L5: الإفصاح عن العجز أو الفروقات | O5: E,V,C | V5: (خارجي) Existence – Valuation – Completeness / (داخلي) حماية النقدية – الالتزام بسياسات الصرف – دقة التسجيل
A6: المستوى الرابع | B6: 1101002 | C6: بنك الراجحي | D6: ودائع جارية تحت الطلب | E6: مطابقة شهرية، صلاحيات توقيع مزدوج | F6: IFRS 7 | G6: IAS 7 | H6: سياسات البنوك SOCPA | I6: ISA 505 | J6: مطابقة كشف البنك، مراجعة التسويات البنكية | K6: تعليمات البنك المركزي | L6: الإفصاح عن قيود السحب أو التسهيلات | O6: E,V,P | V6: (خارجي) Existence – Valuation – Presentation / (داخلي) دقة الرصيد البنكي – التوافق مع كشوف البنك – الالتزام بالتفويضات
A7: المستوى الرابع | B7: 1101003 | C7: بنك الأهلي | D7: ودائع جارية بالبنك الأهلي | E7: مطابقة وتسويات بنكية شهرية | F7: IFRS 7 | G7: IAS 7 | H7: تعليمات البنك المركزي السعودي | I7: ISA 505 | J7: مطابقة كشوف البنك، فحص التفويضات | K7: تعليمات البنك المركزي | L7: الإفصاح عن التسهيلات البنكية | O7: E,V,P | V7: (خارجي) Existence – Valuation – Presentation / (داخلي) دقة الرصيد البنكي – التوافق مع كشوف البنك – الالتزام بالتفويضات
A8: المستوى الثالث | B8: 1102 | C8: أعمال تحت التنفيذ | D8: تكاليف مشاريع قيد الإنجاز قصيرة الأجل | E8: إثبات التكاليف وتحميل نسبة الإنجاز | F8: IFRS 15 | G8: IAS 2 | H8: عقود الإنشاء والخدمات SOCPA | I8: ISA 540 | J8: فحص أوامر التشغيل، اعتماد نسب الإنجاز | K8: نظام المنافسات والمشتريات | L8: شرح منهج القياس المستخدم | O8: E,V,P | V8: (خارجي) Existence – Valuation – Presentation / (داخلي) دقة نسب الإنجاز – مطابقة العقود – كفاءة إدارة المشاريع
A9: المستوى الرابع | B9: 1102001 | C9: مشروع إنشاءات الرياض | D9: تكاليف مشروع إنشاءات | E9: نسبة إنجاز، تقييم بالتكلفة حتى الإنجاز | F9: IFRS 15 | G9: — | H9: سياسات عقود الإنشاء | I9: ISA 540 | J9: مطابقة العقود والفواتير وأوامر التشغيل | K9: نظام المنافسات | L9: الإفصاح عن نسب الإنجاز | O9: E,V,P | V9: (خارجي) Existence – Valuation – Presentation / (داخلي) دقة نسب الإنجاز – مطابقة العقود – كفاءة إدارة المشاريع
A10: المستوى الرابع | B10: 1102002 | C10: مشروع صيانة جدة | D10: تكاليف مشروع صيانة | E10: الاعتراف بالتكاليف الفعلية فقط حتى الإنجاز | F10: IFRS 15 | G10: — | H10: سياسات عقود الخدمات | I10: ISA 540 | J10: فحص تقارير الإنجاز والفواتير | K10: نظام المنافسات | L10: الإفصاح عن العقود الجارية | O10: E,V,P | V10: (خارجي) Existence – Valuation – Presentation / (داخلي) دقة نسب الإنجاز – مطابقة العقود – كفاءة إدارة المشاريع
A11: المستوى الثالث | B11: 1103 | C11: ذمم وأرصدة مدينة تجارية | D11: مطالبات على العملاء مقابل مبيعات | E11: قياس بالقيمة المطفأة واحتساب خسائر ائتمانية متوقعة | F11: IFRS 9 | G11: IAS 1 / IAS 32 | H11: SOCPA للذمم التجارية | I11: ISA 505 / 540 | J11: مصادقات العملاء، تحليل تقادم الذمم | K11: نظام الفوترة الإلكترونية (ZATCA) | L11: الإفصاح عن الذمم الجوهرية | O11: E,V,C | V11: (خارجي) Existence – Valuation – Completeness / (داخلي) دقة تسجيل الذمم – الالتزام بسياسات الائتمان – مراقبة التحصيل
A12: المستوى الرابع | B12: 1103001 | C12: العميل أحمد | D12: ذمة عميل محدد | E12: متابعة التحصيل ضمن دورة الائتمان | F12: IFRS 9 | G12: — | H12: سياسات التحصيل | I12: ISA 505 | J12: مصادقة الرصيد ومراجعة العقود | K12: النظام التجاري | L12: الإفصاح عن الذمم المتعثرة | O12: E,V,P | V12: (خارجي) Existence – Valuation – Presentation / (داخلي) دقة تسجيل الذمم – الالتزام بسياسات الائتمان – مراقبة التحصيل
A13: المستوى الرابع | B13: 1103002 | C13: العميل محمد | D13: ذمة عميل محدد | E13: قياس بالقيمة المطفأة ومخصص ECL | F13: IFRS 9 | G13: — | H13: قواعد الائتمان | I13: ISA 505 | J13: مصادقات وتحليل تقادم | K13: النظام التجاري | L13: الإفصاح عن الذمم الجوهرية | O13: E,V,P | V13: (خارجي) Existence – Valuation – Presentation / (داخلي) دقة تسجيل الذمم – الالتزام بسياسات الائتمان – مراقبة التحصيل
A14: المستوى الثالث | B14: 1104 | C14: المخزون السلعي (البضاعة) | D14: مخزون محتفظ به للبيع ضمن النشاط العادي | E14: القياس بالتكلفة أو صافي القيمة القابلة للتحقق أيهما أقل | F14: — | G14: IAS 2 | H14: SOCPA للمخزون | I14: ISA 501 | J14: حضور الجرد، اختبار القطع والتسعير | K14: لوائح الجرد | L14: ZATCA | M14: الإفصاح عن طريقة التسعير | O14: E,V,C | V14: (خارجي) Existence – Valuation – Completeness / (داخلي) حماية المخزون – كفاءة إدارة المخزون – دقة الجرد
A15: المستوى الرابع | B15: 1104001 | C15: مخزن الرياض | D15: مخزون بضاعة في موقع الرياض | E15: تطبيق FIFO أو المتوسط المرجح | F15: — | G15: IAS 2 | H15: سياسات المخزون | I15: ISA 501 | J15: حضور جرد الموقع، مطابقة البطاقات | K15: لوائح الجرد | L15: ZATCA | M15: الإفصاح عن المخزون المرهون
A16: المستوى الرابع | B16: 1104002 | C16: مخزن جدة | D16: مخزون بضاعة في موقع جدة | E16: تقييم بالتكلفة أو NRV | F16: — | G16: IAS 2 | H16: سياسات المخزون | I16: ISA 501 | J16: اختبار القصاصات والجرد الدوري | K16: لوائح الجرد | L16: ZATCA | M16: الإفصاح عن طرق التسعير | O16: E,V,C | V16: (خارجي) Existence – Valuation – Completeness / (داخلي) حماية المخزون – كفاءة إدارة المخزون – دقة الجرد
O17: E,V,C | V17: (خارجي) Existence – Valuation – Completeness / (داخلي) حماية المخزون – كفاءة إدارة المخزون – دقة الجرد
O18: E,V,P | V18: (خارجي) Existence – Valuation – Presentation / (داخلي) دقة التسجيل – متابعة التحصيل – الامتثال للسياسات
O19: E,R,V | V19: (خارجي) Existence – Rights & Obligations – Valuation / (داخلي) دقة إثبات العمليات – الالتزام بالإفصاح – تسوية دورية
O20: E,V,P | V20: (خارجي) Existence – Valuation – Presentation / (داخلي) دقة الرسملة – الترحيل حسب الفترات – المطابقة الدورية
O21: V,P | V21: (خارجي) Valuation – Presentation / (داخلي) دقة الرسملة – مطابقة عقود القروض – مراجعة جداول الإطفاء
O22: E,V,P | V22: (خارجي) Existence – Valuation – Presentation / (داخلي) إثبات الحقوق – دقة التقييم – الإفصاح عن البنود الجوهرية
O23: E,V,C | V23: (خارجي) Existence – Valuation – Completeness / (داخلي) دقة التحصيل – متابعة الاستحقاقات – مطابقة القيود
O24: E,R,V | V24: (خارجي) Existence – Rights & Obligations – Valuation / (داخلي) سلامة الضمانات – الإفصاح عن الالتزامات – مطابقة البنوك
O25: E,V,P | V25: (خارجي) Existence – Valuation – Presentation / (داخلي) دقة التصنيف – حماية المخزون – منع الاستخدام غير المصرح
O26: E,V,C | V26: (خارجي) Existence – Valuation – Completeness / (داخلي) دقة القطع – ربط بالإيرادات الفعلية – مراقبة الترحيل
O27: E,V,P | V27: (خارجي) Existence – Valuation – Presentation / (داخلي) متابعة التوزيعات – مطابقة الإشعارات – الترحيل الصحيح
A28: المستوى الثالث | B28: 1115 | C28: مواد خام ومهمات | D28: مواد أولية ومهمات تشغيلية | E28: قياس بالتكلفة أو NRV | F28: — | G28: IAS 2 | H28: SOCPA للمخزون | I28: ISA 501 | J28: حضور الجرد وتتبع الصرف | K28: نظام التصنيع | L28: الإفصاح عن الفاقد والهالك
A29: المستوى الرابع | B29: 1115001 | C29: مخزون مواد خام | D29: مخزون مواد خام بالمخزن | E29: تطبيق FIFO أو المتوسط المرجح | F29: — | G29: IAS 2 | H29: سياسات المخزون | I29: ISA 501 | J29: مطابقة أرصدة المخزون | K29: نظام التصنيع | L29: الإفصاح عن انخفاض القيمة
A30: المستوى الرابع | B30: 1115002 | C30: مهمات تشغيل | D30: أدوات ومهمات تستخدم في التشغيل | E30: تحميل كمخزون مستهلك عند الاستخدام | F30: — | G30: IAS 2 | H30: سياسات المخزون | I30: ISA 501 | J30: فحص الاستهلاك الفعلي | K30: نظام التصنيع | L30: الإفصاح عن الفاقد
A31: المستوى الثالث | B31: 1116 | C31: إنتاج تحت التشغيل | D31: منتجات لم تكتمل بعد | E31: تحميل المواد والأجور والتكاليف الصناعية | F31: — | G31: IAS 2 | H31: SOCPA للتكاليف | I31: ISA 540 | J31: مطابقة أوامر الإنتاج | K31: نظام العمل الصناعي | L31: الإفصاح عن نسب الإتمام
A32: المستوى الرابع | B32: 1116001 | C32: إنتاج تحت التشغيل خط 1 | D32: منتجات جارية بخط الإنتاج الأول | E32: تحميل فعلي للمواد والأجور والتكاليف الصناعية | F32: — | G32: IAS 2 | H32: سياسات التكاليف | I32: ISA 540 | J32: مطابقة التكاليف مع الإنتاج الفعلي | K32: نظام العمل الصناعي | L32: الإفصاح عن الفاقد الطبيعي
A33: المستوى الرابع | B33: 1116002 | C33: إنتاج تحت التشغيل خط 2 | D33: منتجات جارية بخط الإنتاج الثاني | E33: تحميل فعلي للمواد والأجور والتكاليف الصناعية | F33: — | G33: IAS 2 | H33: سياسات التكاليف | I33: ISA 540 | J33: مطابقة التكاليف مع الإنتاج الفعلي | K33: نظام العمل الصناعي | L33: الإفصاح عن الفاقد الطبيعي
A34: المستوى الثالث | B34: 1117 | C34: إنتاج تام | D34: منتجات مكتملة غير مباعة | E34: القياس بالتكلفة أو NRV أيهما أقل | F34: — | G34: IAS 2 | H34: سياسات المخزون | I34: ISA 501 | J34: اختبارات القطع والقصاصات | K34: نظام التصنيع | L34: الإفصاح عن طريقة التقييم
A35: المستوى الرابع | B35: 1117001 | C35: مخزون إنتاج تام | D35: منتجات مكتملة جاهزة للبيع | E35: التكلفة أو NRV أيهما أقل | F35: — | G35: IAS 2 | H35: سياسات المخزون | I35: ISA 501 | J35: حضور الجرد واختبار التسعير | K35: نظام التصنيع | L35: الإفصاح عن NRV
A36: المستوى الثاني | B36: 12 | C36: الموجودات غير المتداولة | D36: أصول يُتوقع استخدامها أو الاحتفاظ بها لأكثر من 12 شهر | E36: نموذج التكلفة أو إعادة التقييم | F36: IFRS 13 | G36: IAS 1 | H36: إطار العرض العام SOCPA | I36: ISA 315 / 330 | J36: فحص وجود وتصنيف الأصول طويلة الأجل | K36: نظام الشركات | L36: الإفصاح عن أسس التصنيف وطبيعة الأصول | O36: E,C,R,V,P | V36: (خارجي) جميع أهداف المراجعة / (داخلي) حماية الأصول الثابتة – دقة التقييم – متابعة الإهلاك
A37: المستوى الثالث | B37: 1201 | C37: أصول غير ملموسة | D37: أصول ليس لها جوهر مادي وتُستخدم لفترات طويلة | E37: رسملة عند توافر المعايير ثم إطفاء أو اختبار هبوط | F37: — | G37: IAS 38 | H37: سياسات رسملة وتقييم الأصول غير الملموسة | I37: SOCPA | J37: ISA 540 | K37: مراجعة عقود الملكية الفكرية؛ اختبار الهبوط | L37: نظام الملكية الفكرية | M37: الإفصاح عن أعمار الإطفاء والمنهج | O37: E,R,V,P | V37: (خارجي) Existence – Rights & Obligations – Valuation – Presentation / (داخلي) حماية الملكية الفكرية – دقة الإطفاء – مراجعة القيود القانونية
A38: المستوى الرابع | B38: 1201001 | C38: برامج حاسوبية | D38: أصول برمجية تُستخدم في التشغيل والإدارة | E38: رسملة التكاليف المباشرة وإطفاء على العمر النافع | F38: — | G38: IAS 38 | H38: سياسات الرسملة والإطفاء | I38: SOCPA | J38: ISA 540 | K38: مراجعة فواتير الترخيص وجدولة الإطفاء | L38: نظام حماية حقوق المؤلف | M38: الإفصاح عن العمر الإنتاجي وطريقة الإطفاء | O38: E,V,P | V38: (خارجي) Existence – Valuation – Presentation / (داخلي) حماية الأصول – دقة الإطفاء – التحقق من الرخص
A39: المستوى الرابع | B39: 1201002 | C39: براءات اختراع | D39: حقوق ملكية فكرية مسجلة قانوناً | E39: رسملة عند الشراء وإطفاء على العمر النافع | F39: — | G39: IAS 38 | H39: سياسات الملكية الفكرية | I39: SOCPA | J39: ISA 540 | K39: فحص عقود الملكية وسندات التسجيل | L39: نظام الملكية الفكرية | M39: الإفصاح عن القيود القانونية أو الرهون | O39: E,R,V | V39: (خارجي) Existence – Rights & Obligations – Valuation / (داخلي) حماية الملكية الفكرية – دقة الإطفاء – مراجعة القيود القانونية
A40: المستوى الثالث | B40: 1202 | C40: أصول بموجب عقود إيجار تمويلي | D40: أصول ثابتة مستأجرة طويلة الأجل | E40: إثبات أصل حق الاستخدام والتزام إيجار | F40: IFRS 16 | G40: — | H40: سياسات عقود الإيجار | I40: SOCPA | J40: ISA 540 | K40: فحص عقود الإيجار وحساب الفوائد الضمنية | L40: نظام الإيجارات | M40: الإفصاح عن آجال الاستحقاق والضمانات | O40: E,R,V | V40: (خارجي) Existence – Rights & Obligations – Valuation / (داخلي) سلامة الأصول المؤجرة – دقة قيود الإيجار – مطابقة جداول السداد
...

Sheet دليل المراجعة
A1: المستوى | B1: فاصل | C1: رقم | D1: البيان | E1: الغرض | F1: المسؤول | G1: تاريخ الإعداد | H1: تاريخ المراجعة | I1: الاستنتاج | J1: مرفقات/روابط
A2: الأول | B2: ع | C2: ع | D2: ملف عموميات | E2: تعريف عام بالعميل والمستندات الرئيسية | K2: الحقل | L2: القيمة | M2: ملاحظات
A3: الأول | B3: ن | C3: ن | D3: الملف الإداري للمراجعة | E3: إدارة العملية والاتفاقيات | K3: اسم العميل | M3: اختياري
A4: الثاني | B4: ن1 | C4: ن1-1 | D4: استقلالية فريق العمل | E4: التأكد من الاستقلال وعدم التعارض | K4: نهاية السنة المالية | L4: 31/12/2024 | M4: صيغة تاريخ
A5: الثاني | B5: ن1 | C5: ن1-2 | D5: قبول العملاء واستمرارية العلاقة (Go/No-Go) | E5: قرار قبول/استمرار موثق | K5: الإطار المحاسبي | L5: IFRS
A6: الثاني | B6: ن1 | C6: ن1-3 | D6: التواصل مع المراجع السابق | E6: الامتثال للمتطلبات المهنية | K6: الإطار المهني للمراجعة | L6: ISAs
A7: الثاني | B7: ن1 | C7: ن1-4 | D7: خطاب الارتباط/محضر التعيين | E7: تحديد نطاق ومسؤوليات المراجعة | K7: المُعدّ | M7: اسم المدقق
A8: الثالث | B8: ع2 | C8: ع2-1 | D8: استبيانات الرقابة الداخلية حسب الدورات | E8: توثيق الفهم وتقييم المخاطر | K8: المراجع | M8: اسم المدير/الشريك
A9: الثالث | B9: ع2 | C9: ع2-2 | D9: قائمة الاستقصاء (Understanding & Documentation) | E9: فهم المنشأة وبيئتها | K9: (أ) اختيار المعيار (Benchmark) | L9: الربح قبل الضريبة | M9: اختر: الربح قبل الضريبة / الإيرادات / إجمالي الأصول / حقوق الملكية / متوسط ربح 3-5 سنوات / آخر
A10: الثالث | B10: ع2 | C10: ع2-3 | D10: مكافحة غسل الأموال وتمويل الإرهاب | E10: امتثال القوانين ذات العلاقة | K10: (ب) قيمة المعيار المختار | L10: 0 | M10: أدخل رقمًا
A11: الثالث | B11: ع2 | C11: ع2-4 | D11: تقييم الدفاتر والأنظمة (متطلبات اللغة العربية) | E11: امتثال تنظيمي وتقني | K11: (ج) النسبة المختارة للأهمية الشاملة (OM) | L11: 0.05 | M11: النطاقات الشائعة: PBT 5–10%، الإيرادات 0.5–2%، الأصول 1–2%، حقوق الملكية 1%
A12: الثالث | B12: ع2 | C12: ع2-5 | D12: اختبار معالجات النظام (ITAC) – مُحدَّث | E12: ضوابط مدخلات/معالجة/مخرجات | F12: متخصص نظم | K12: الأهمية الشاملة (Overall Materiality - OM) | L12: =VALUE(SUBSTITUTE(C9,"%",""))/100 * C8 -> #VALUE! | M12: حساب تلقائي = (نسبة ج × قيمة ب)
A13: الثاني | B13: ن2 | C13: ن2-1 | D13: ميزان المراجعة العام والحسابات التحليلية | E13: قاعدة بيانات الحسابات | K13: نسبة الأهمية للأداء (Performance Materiality %) | L13: 0.6 | M13: عادةً 50–75% وفقًا للمخاطر
A14: الثاني | B14: ن2 | C14: ن2-2 | D14: مذكرة التخطيط ومخاطر المراجعة (Risk-Based) | E14: استراتيجية واستجابات المراجعة | K14: الأهمية للأداء (PM) | L14: =VALUE(SUBSTITUTE(C12,"%",""))/100 * C11 -> #VALUE! | M14: حساب تلقائي = نسبة PM × OM
A15: الثاني | B15: ن2 | C15: ن2-2-ISA240 | D15: ورقة الغش (ISA 240) | E15: تقييم مخاطر الغش وإجراءات غير متوقعة | K15: نسبة حدّ التجميع (Posting/Trivial Threshold %) | L15: 0.05 | M15: عادةً 3–10% من OM
A16: الثاني | B16: ن2 | C16: ن2-2-ISA250 | D16: القوانين والأنظمة (ISA 250) | E16: تحديد وعدم الامتثال المحتمل | K16: حدّ التجميع (Posting Threshold) | L16: =VALUE(SUBSTITUTE(C14,"%",""))/100 * C11 -> #VALUE! | M16: حساب تلقائي = نسبة × OM
A17: الثاني | B17: ن2 | C17: ن2-2-ISA260 | D17: الاتصال مع الحوكمة (ISA 260) | E17: قناة اتصال ومحتوى الاجتماعات | K17: ملاحظات قرار المعيار | M17: اذكر سبب اختيار المعيار والنسبة بالرجوع لطبيعة النشاط والمخاطر
A18: الثاني | B18: ن2 | C18: ن2-2-ISA540 | D18: التقديرات المحاسبية (ISA 540 Updated) | E18: تقييم التحيز والنطاقات الحساسة
A19: الثاني | B19: ن2 | C19: ن2-2-ISA550 | D19: الأطراف ذات العلاقة (ISA 550) | E19: تعريف واختبار المعاملات غير العادية
A20: الثاني | B20: ن2 | C20: ن2-2-ISA560 | D20: الأحداث اللاحقة (ISA 560) | E20: بحث وتقييم الأثر اللاحق
A21: الثاني | B21: ن2 | C21: ن2-2-ISA570 | D21: الاستمرارية (ISA 570) | E21: مؤشرات وشواهد وخطط الإدارة
A22: الثاني | B22: ن2 | C22: ن2-8 | D22: الأهمية النسبية والأهمية للأداء | E22: تحديد المادية وحدود التجميع | F22: مدير المراجعة
A23: الثاني | B23: ن2 | C23: ن2-8-530 | D23: المعاينة الإحصائية (ISA 530) | E23: تحديد حجم العينة وتقييم النتائج
A24: الثالث | B24: ن4 | C24: ن4-AR | D24: الذمم المدينة والمبيعات | E24: تأكيدات، Cut-off، كفاية المخصصات
A25: الثالث | B25: ن4 | C25: ن4-AP | D25: الدائنون والمشتريات | E25: مطابقات، Cut-off، التزامات محتملة
A26: الثالث | B26: ن4 | C26: ن4-INV | D26: المخزون والجرد | E26: إجراءات حضور الجرد/العدّات المفاجئة
A27: الثالث | B27: ن4 | C27: ن4-CASH | D27: النقدية والبنوك | E27: مطابقات، مصادقات، ضوابط الشيكات
A28: الثالث | B28: ن4 | C28: ن4-FA | D28: الأصول الثابتة | E28: الإضافة/الاستبعاد/الإهلاك/الهبوط
A29: الثالث | B29: ن4 | C29: ن4-REVOTH | D29: إيرادات/مصروفات أخرى | E29: تحليلات ومسوغات
A30: الثالث | B30: ن4 | C30: ن4-TAX | D30: الزكاة والضريبة وVAT/ZATCA | E30: مطابقة الإقرارات والفوترة الإلكترونية
A31: الثالث | B31: ن4 | C31: ن4-FIN | D31: الأدوات المالية | E31: IFRS 9 وخسائر ائتمانية متوقعة
A32: الثالث | B32: ن4 | C32: ن4-LIAB | D32: الالتزامات والاحتياطيات | E32: قضايا وتعهدات، التزامات محتملة
A33: الثالث | B33: ن4 | C33: ن4-EQUITY | D33: حقوق الملكية والتوزيعات | E33: امتثال نظامي ومحاضر
A34: الرابع | B34: صناعة-مقاولات | C34: IND-CONTRACTS | D34: ملف عقود المشاريع (IFRS 15) | E34: الالتزامات/VOs/Retention/WIP/تكلفة لاستكمال
... A43: الثالث | B43: ن6 | C43: ن6-CONS | D43: أوراق توحيد وترحيل فروقات | E43: إزالة التعاملات البينية والسياسات
A44: الثالث | B44: IT | C44: IT-ITGC | D44: برنامج ITGC | E44: صلاحيات، فصل واجبات، تغييرات النظام، نسخ احتياطي | F44: متخصص نظم
A45: الثالث | B45: IT | C45: IT-Reports | D45: ضوابط تقارير النظام | E45: إثبات اتساق التقارير مع الأستاذ العام
A46: الثالث | B46: REP | C46: REP-TMPL | D46: نماذج تقارير المراجع (غير/معدّل، KAMs) | E46: اتساق الصياغة مع المعايير
A47: الثالث | B47: REP | C47: REP-MNG | D47: خطاب الإدارة بالملاحظات | E47: تصنيف المخاطر وخطة المعالجة
A48: الثالث | B48: FIN | C48: FIN-POST | D48: القوائم المالية بعد الاعتماد | E48: نسخة نهائية مع إفصاحات
...

Sheet دليل مراحل الملف
A1: كود المرحلة | B1: المرحلة | C1: نوع المنشأة | D1: القطاع الاقتصادي | E1: الإجراء | F1: نطاق الإجراء | G1: طريقة الاختيار | H1: أمثلة الاستخدام | I1: IAS | J1: IFRS | K1: ISA | L1: السياسات ذات العلاقة | M1: الشرح التفصيلي للمرحلة | N1: النماذج الواجب تعبئتها | O1: إجراءات المراجعة العملية | P1: المخاطر المرتبطة | Q1: مستوى المخاطر | R1: الجهة المسؤولة | S1: المخرجات | T1: مدة التنفيذ | U1: نقاط القوة | V1: نقاط الضعف المحتملة | W1: مؤشرات الأداء
A2: 1 | B2: قبول العميل | E2: التحقق من نزاهة الإدارة والملاك | F2: جميع الحسابات | G2: استفسار + مستند | H2: استبيان / محاضر الاجتماعات | I2: IAS 1 | J2: IFRS 10 | K2: ISA 210 | L2: سياسة قبول العميل | M2: فحص السمعة والامتثال القانوني | N2: ✔ استبيان النزاهة ✔ خطاب قبول العميل | O2: مراجعة محاضر التأسيس – التحقق من النزاعات – الحصول على تأكيدات مكتوبة | P2: قبول عميل غير مناسب، غسل الأموال | Q2: عالي | R2: الشريك المسؤول + فريق القبول | S2: خطاب قبول | T2: قبل التعاقد | U2: تعزيز الثقة وحماية السمعة | V2: الاعتماد على بيانات العميل فقط | W2: % العملاء المقبولين بعد الفحص
A3: 1.1 | B3: تحليل خلفية العميل | E3: مراجعة الوضع القانوني | F3: السجل التجاري | G3: تحليل وثائق | H3: رخصة، سجل تجاري | I3: IAS 1 | J3: IFRS 10 | K3: ISA 210 | L3: سياسة قبول العميل | M3: التحقق من سلامة الوضع القانوني | N3: ✔ استبيان الخلفية | O3: مراجعة مستندات التسجيل والتراخيص | P3: قبول عميل غير قانوني | Q3: متوسط | R3: فريق القبول | S3: ورقة تقييم خلفية | T3: يوم | U3: توثيق قانوني | V3: نقص بيانات | W3: % اكتمال بيانات العميل
A4: 1.1.1 | B4: فحص الوضع المالي | E4: تحليل القوائم المالية | F4: بيانات مالية | G4: تحليل نسبي | H4: تحليل نسب | I4: IAS 1 | J4: IFRS 10 | K4: ISA 210 | L4: سياسة قبول العميل | M4: ضمان الملاءة المالية | N4: ✔ نموذج تقييم مالي | O4: تحليل نسب السيولة والربحية | P4: قبول عميل متعثر ماليًا | Q4: مرتفع | R4: فريق القبول | S4: ورقة عمل تحليل مالي | T4: يوم | U4: كشف مبكر للمخاطر | V4: اعتماد على أرقام غير مدققة | W4: % التقييمات المالية المكتملة
A5: 1.1.2 | B5: فحص السمعة | E5: تحقق خارجي | F5: جهات تنظيمية | G5: استفسارات | H5: محاضر / تقارير | I5: IAS 1 | J5: IFRS 10 | K5: ISA 210 | L5: سياسة قبول العميل | M5: ضمان السمعة الجيدة | N5: ✔ خطاب استفسار | O5: مراسلات رسمية – بحث في قواعد بيانات | P5: سمعة سلبية | Q5: مرتفع | R5: الشريك المسؤول | S5: تقرير سمعة | T5: يوم | U5: حماية سمعة المكتب | V5: تأخر الردود الخارجية | W5: % الردود المستلمة
A6: 1.2 | B6: توثيق قبول العميل | E6: اعتماد القبول | F6: إدارة الجودة | G6: اعتماد داخلي | H6: استمارة موافقة | I6: IAS 1 | J6: IFRS 10 | K6: ISA 210 | L6: سياسة قبول العميل | M6: اعتماد رسمي قبل التعاقد | N6: ✔ نموذج موافقة | O6: اعتماد الشريك – حفظ المستندات | P6: البدء بدون موافقة | Q6: متوسط | R6: الشريك المسؤول | S6: موافقة رسمية | T6: ساعات | U6: توثيق رسمي | V6: نسيان التوقيع | W6: % وجود موافقات موثقة
A7: 1.2.1 | B7: حفظ المستندات | E7: تجهيز الملف | F7: الملف الإلكتروني | G7: إدخال يدوي | H7: مجلد عميل | I7: IAS 1 | J7: IFRS 10 | K7: ISA 210 | L7: سياسة قبول العميل | M7: سهولة الوصول للبيانات | N7: ✔ قائمة محتويات الملف | O7: رفع المستندات للنظام | P7: ضياع مستندات | Q7: منخفض | R7: مساعد إداري | S7: ملف مكتمل | T7: يوم | U7: سهولة الاسترجاع | V7: عدم تحديث المحتوى | W7: % الملفات المكتملة
A8: 1.2.2 | B8: التأكيد مع العميل | E8: إشعار قبول | F8: البريد الرسمي | G8: إرسال بريد | H8: خطاب رسمي | I8: IAS 1 | J8: IFRS 10 | K8: ISA 210 | L8: سياسة قبول العميل | M8: إبلاغ العميل ببدء المهمة | N8: ✔ خطاب قبول | O8: إرسال بريد تأكيد | P8: بدء العمل قبل إخطار العميل | Q8: منخفض | R8: مساعد إداري | S8: بريد تأكيد | T8: ساعات | U8: شفافية | V8: نسيان الإرسال | W8: % العملاء المبلغين
A9: 2 | B9: الاستقلالية | E9: تقييم استقلال فريق المراجعة | F9: عملية المراجعة | G9: استقصاء فردي | H9: نماذج إفصاح الاستقلالية | I9: — | J9: — | K9: ISA 220 | L9: سياسة الاستقلالية | M9: ضمان موضوعية الرأي والاستقلالية المهنية | N9: ✔ نموذج إفصاح الاستقلالية ✔ سجل تضارب المصالح | O9: مراجعة تضارب المصالح وتطبيق سياسة التدوير | P9: تضارب مصالح | Q9: عالي | R9: الشريك المسؤول | S9: نموذج موقع | T9: قبل المهمة | U9: شفافية | V9: مقاومة الموظفين | W9: % النماذج المكتملة
A10: 2.1 | B10: فحص تضارب المصالح | E10: استبيان استقلالية | F10: كل الأعضاء | G10: استقصاء | H10: نموذج إفصاح | I10: — | J10: — | K10: ISA 220 | L10: سياسة الاستقلالية | M10: منع تضارب المصالح | N10: ✔ نموذج إفصاح | O10: تحليل العلاقات | P10: فقد الاستقلالية | Q10: عالي | R10: كل عضو | S10: نماذج مكتملة | T10: ساعات | U10: ضمان موضوعية | V10: رفض الإفصاح | W10: % النماذج المستلمة
A11: 2.1.1 | B11: مراجعة التعيينات السابقة | E11: تحليل مهام سابقة | F11: السجلات | G11: مراجعة سجلات | H11: كشف مهام سابقة | I11: — | J11: — | K11: ISA 220 | L11: سياسة الاستقلالية | M11: التأكد من عدم استمرار عميل سابق | N11: ✔ سجل تعيينات | O11: فحص المهام السابقة | P11: استمرار علاقات سابقة | Q11: متوسط | R11: مسؤول الجودة | S11: ورقة مراجعة | T11: يوم | U11: فصل الأدوار | V11: سهو في السجلات | W11: % المهام المفصولة
A12: 2.1.2 | B12: مراجعة العلاقات الشخصية | E12: فحص علاقات شخصية | F12: الهيكل الإداري | G12: استفسارات | H12: قائمة أسماء | I12: — | J12: — | K12: ISA 220 | L12: سياسة الاستقلالية | M12: منع تأثير العلاقات الشخصية | N12: ✔ استبيان علاقات | O12: استقصاء علاقات مباشرة | P12: تأثير شخصي | Q12: متوسط | R12: الشريك المسؤول | S12: قائمة موقعة | T12: يوم | U12: حماية الحياد | V12: كتمان الموظفين | W12: % الإفصاحات الصحيحة
A13: 2.2 | B13: اعتماد الاستقلالية | E13: توثيق الاستقلالية | F13: إدارة الجودة | G13: موافقة | H13: اعتماد داخلي | I13: — | J13: — | K13: ISA 220 | L13: سياسة الاستقلالية | M13: توثيق استقلالية الفريق | N13: ✔ سجل اعتماد | O13: مراجعة توقيعات الشريك | P13: عدم وجود موافقة | Q13: منخفض | R13: الشريك المسؤول | S13: اعتماد موقع | T13: ساعات | U13: توثيق | V13: نسيان التوقيع | W13: % الموافقات المكتملة
A14: 2.2.1 | B14: حفظ النماذج | E14: حفظ نماذج الإفصاح | F14: النظام الإلكتروني | G14: إدخال يدوي | H14: مجلد مستقل | I14: — | J14: — | K14: ISA 220 | L14: سياسة الاستقلالية | M14: سهولة الوصول لاحقًا | N14: ✔ قائمة ملفات | O14: رفع المستندات للنظام | P14: ضياع نماذج | Q14: منخفض | R14: مساعد إداري | S14: ملف مكتمل | T14: يوم | U14: سهولة الاسترجاع | V14: عدم تحديث الملف | W14: % الملفات المكتملة
A15: 2.2.2 | B15: مراجعة دورية | E15: مراجعة سنوية | F15: كل الفريق | G15: مراجعة دورية | H15: جدول متابعة | I15: — | J15: — | K15: ISA 220 | L15: سياسة الاستقلالية | M15: التحقق من استمرار الاستقلالية | N15: ✔ جدول متابعة | O15: فحص علاقات سنويًا | P15: فقد الاستقلالية | Q15: متوسط | R15: مسؤول الجودة | S15: محضر مراجعة | T15: يوم | U15: استدامة الالتزام | V15: نسيان التحديث | W15: % المراجعات السنوية
A16: 3 | B16: الأهمية النسبية | E16: تحديد مستويات الأهمية النسبية | F16: بنود القوائم المالية | G16: تحليل كمي ونوعي | H16: نسب من صافي الربح/الأصول | I16: IAS 8 | J16: IFRS 8 | K16: ISA 320 | L16: سياسة التقدير المهني | M16: تركيز الفحص على البنود الجوهرية | N16: ✔ جدول الأهمية النسبية ✔ ورقة عمل تقدير | O16: احتساب نسب من الربح/الأصول – استخدام الحكم المهني | P16: إهمال بنود جوهرية | Q16: متوسط | R16: فريق التخطيط | S16: ورقة عمل | T16: يوم | U16: تركيز الجهد | V16: تقدير غير دقيق | W16: % صحة التقديرات
A17: 3.1 | B17: تحديد العتبات | E17: تحديد نسب الأهمية | F17: القوائم المالية | G17: تحليل رقمي | H17: نسب الربح/الأصول | I17: IAS 8 | J17: IFRS 8 | K17: ISA 320 | L17: سياسة التقدير المهني | M17: حساب نسب مادية معتمدة | N17: ✔ ورقة عتبات | O17: حساب العتبات لكل بند | P17: تحديد غير ملائم | Q17: متوسط | R17: المراجع الرئيسي | S17: ورقة عمل | T17: يوم | U17: وضوح المعيار | V17: تغيرات غير مبررة | W17: % مطابقة العتبات
A18: 3.1.1 | B18: تحليل المخاطر | E18: ربط المخاطر بالأهمية | F18: كل البنود | G18: تحليل نوعي | H18: مصفوفة مخاطر | I18: IAS 8 | J18: IFRS 8 | K18: ISA 320 | L18: سياسة التقدير المهني | M18: توجيه الجهد للبنود عالية المخاطر | N18: ✔ مصفوفة مخاطر | O18: ربط كل بند بمستوى خطر | P18: تجاهل عناصر عالية المخاطر | Q18: مرتفع | R18: المراجع الرئيسي | S18: ورقة تحليل | T18: يوم | U18: تركيز الجهد | V18: تقدير خاطئ | W18: ن
A19: 3.1.2 | B19: توثيق الأحكام المهنية | E19: سجل التقديرات | F19: ورقة التقديرات | G19: توثيق يدوي | H19: مذكرة مهنية | I19: IAS 8 | J19: IFRS 8 | K19: ISA 320 | L19: سياسة التقدير المهني | M19: إثبات الأحكام المتخذة | N19: ✔ مذكرة تقديرات | O19: توثيق أسباب الاختيار | P19: صعوبة المراجعة لاحقًا | Q19: متوسط | R19: المراجع الرئيسي | S19: مذكرة موقعة | T19: يوم | U19: سهولة المراجعة | V19: نقص التفاصيل | W19: % الأوراق الموقعة
A20: 3.2 | B20: اعتماد الأهمية | E20: اعتماد داخلي | F20: إدارة الجودة | G20: موافقة | H20: نموذج اعتماد | I20: IAS 8 | J20: IFRS 8 | K20: ISA 320 | L20: سياسة التقدير المهني | M20: اعتماد رسمي للعتبات | N20: ✔ نموذج اعتماد | O20: اعتماد الشريك المسؤول | P20: البدء بدون اعتماد | Q20: منخفض | R20: الشريك المسؤول | S20: اعتماد موقّع | T20: ساعات | U20: توثيق رسمي | V20: نسيان الاعتماد | W20: % النماذج المعتمدة
A21: 3.2.1 | B21: مراجعة دورية | E21: مراجعة خلال التنفيذ | F21: البنود الجوهرية | G21: مراجعة | H21: ورقة متابعة | I21: IAS 8 | J21: IFRS 8 | K21: ISA 320 | L21: سياسة التقدير المهني | M21: ضبط الخطة حسب التغيرات | N21: ✔ ورقة متابعة | O21: مقارنة بالتنفيذ الفعلي | P21: عدم التحديث | Q21: منخفض | R21: فريق التخطيط | S21: ورقة محدثة | T21: يوم | U21: مرونة | V21: تأخر التحديث | W21: % تحديثات العتبات
A22: 3.2.2 | B22: مشاركة الفريق | E22: إعلام جميع الأعضاء | F22: الفريق كامل | G22: اجتماع | H22: عرض تقديمي | I22: IAS 8 | J22: IFRS 8 | K22: ISA 320 | L22: سياسة التقدير المهني | M22: ضمان علم جميع الفريق بالحدود | N22: ✔ محضر اجتماع | O22: عرض في الاجتماع الافتتاحي | P22: سوء تطبيق | Q22: منخفض | R22: قائد المهمة | S22: محضر حضور | T22: ساعات | U22: توحيد الفهم | V22: ضعف التركيز | W22: % الحضور المطلعين
A23: 4 | B23: تقييم الرقابة الداخلية | E23: مراجعة نظام الرقابة على النقد | F23: النقدية بالصندوق | G23: استقصاء وملاحظة | H23: استبيان / جرد مفاجئ | I23: IAS 7 | J23: IFRS 9 | K23: ISA 315 | L23: سياسة الرقابة الداخلية | M23: التأكد من وجود ضوابط تحد من الأخطاء | N23: ✔ استبيان الرقابة ✔ نموذج جرد نقدية | O23: جرد مفاجئ – مراجعة التسويات البنكية | P23: ضعف الضوابط | Q23: عالي | R23: فريق المراجعة | S23: ورقة عمل | T23: يوم | U23: كشف نقاط الضعف | V23: مقاومة الموظفين | W23: % الضوابط المختبرة
A24: 4.1 | B24: تقييم التصميم | E24: مراجعة تصميم الضوابط | F24: كل الأقسام | G24: ملاحظة واستقصاء | H24: استبيان تصميم | I24: IAS 7 | J24: IFRS 9 | K24: ISA 315 | L24: سياسة الرقابة الداخلية | M24: تحديد الفجوات في التصميم | N24: ✔ استبيان تصميم | O24: مقابلات مع مسؤولي العمليات | P24: ضوابط مصممة بشكل سيئ | Q24: عالي | R24: المراجع المساعد | S24: ورقة تقييم | T24: يوم | U24: كشف العيوب | V24: ضعف المعرفة | W24: % الفجوات المحددة
A25: 4.1.1 | B25: اختبار التنفيذ | E25: فحص تشغيل الضوابط | F25: العينات المختارة | G25: اختبار عملي | H25: فحص مستندات | I25: IAS 7 | J25: IFRS 9 | K25: ISA 315 | L25: سياسة الرقابة الداخلية | M25: التحقق من تطبيق الضوابط | N25: ✔ ورقة اختبارات | O25: فحص مستندات تنفيذ | P25: عدم الالتزام بالضوابط | Q25: عالي | R25: المراجع الميداني | S25: ورقة نتائج | T25: يوم | U25: توثيق | V25: قلة أدلة | W25: % نسبة الالتزام
A26: 4.1.2 | B26: تقييم فعالية الرقابة | E26: تحليل نتائج الاختبارات | F26: الضوابط الرئيسية | G26: تحليل | H26: ورقة تحليل | I26: IAS 7 | J26: IFRS 9 | K26: ISA 315 | L26: سياسة الرقابة الداخلية | M26: تقييم فاعلية النظام | N26: ✔ ورقة تحليل | O26: تحليل انحرافات النتائج | P26: فشل النظام | Q26: متوسط | R26: المراجع الرئيسي | S26: ورقة تقييم | T26: يوم | U26: تحسين الضوابط | V26: سوء التقدير | W26: % فعالية الضوابط
A27: 4.2 | B27: توثيق النتائج | E27: توثيق الفحص | F27: نظام الأرشفة | G27: إدخال الكتروني | H27: ملف رقابة | I27: IAS 7 | J27: IFRS 9 | K27: ISA 315 | L27: سياسة الرقابة الداخلية | M27: توثيق نتائج التقييم | N27: ✔ قائمة مرفقات | O27: إدخال النتائج في النظام | P27: فقد التوثيق | Q27: منخفض | R27: مساعد إداري | S27: ملف مكتمل | T27: ساعات | U27: سهولة الرجوع | V27: نسيان الإرفاق | W27: % الملفات المكتملة
A28: 4.2.1 | B28: اعتماد النتائج | E28: اعتماد من الشريك | F28: إدارة الجودة | G28: اعتماد | H28: نموذج توقيع | I28: IAS 7 | J28: IFRS 9 | K28: ISA 315 | L28: سياسة الرقابة الداخلية | M28: اعتماد رسمي | N28: ✔ نموذج توقيع | O28: توقيع إلكتروني | P28: غياب الاعتماد | Q28: منخفض | R28: الشريك المسؤول | S28: اعتماد موقع | T28: ساعات | U28: توثيق | V28: نسيان التوقيع | W28: % النماذج المعتمدة
A29: 4.2.2 | B29: إعداد تقرير الضوابط | E29: تقرير موجز | F29: الإدارة | G29: إصدار | H29: نموذج تقرير | I29: IAS 7 | J29: IFRS 9 | K29: ISA 315 | L29: سياسة الرقابة الداخلية | M29: تقديم النتائج للإدارة | N29: ✔ تقرير رقابة | O29: إعداد التقرير النهائي | P29: عدم تسليم التقرير | Q29: منخفض | R29: المراجع الرئيسي | S29: تقرير رقابة | T29: يوم | U29: تحسين النظام | V29: تأخير | W29: % التقارير المسلمة
A30: 5 | B30: اختبار المعالجات بالحاسب | E30: اختبار الضوابط الإلكترونية والبرامج | F30: النظام المحاسبي | G30: فحص عملي | H30: اختبار مدخلات ومخرجات | I30: IAS 1 | J30: IFRS 7 | K30: ISA 330 | L30: سياسة أمن المعلومات | M30: ضمان دقة المعالجات الآلية | N30: ✔ نموذج اختبار ✔ سجل ضوابط | O30: تجربة إدخال بيانات – فحص سجلات الاستخدام | P30: اختراق إلكتروني | Q30: عالي | R30: فريق المراجعة + IT | S30: تقرير اختبار | T30: يوم | U30: ضمان موثوقية | V30: قصور سيبراني | W30: % الثغرات المكتشفة
A31: 5.1 | B31: اختبار مدخلات النظام | E31: فحص صحة المدخلات | F31: شاشات الإدخال | G31: تجريبي | H31: إدخال بيانات تجريبية | I31: IAS 1 | J31: IFRS 7 | K31: ISA 330 | L31: سياسة أمن المعلومات | M31: التحقق من سلامة الإدخال | N31: ✔ سجل اختبار | O31: إدخال بيانات مزيفة | P31: أخطاء إدخال | Q31: عالي | R31: فريق IT | S31: ورقة نتائج | T31: ساعات | U31: تحقق دقة | V31: إدخالات ناقصة | W31: % الإدخالات الصحيحة
A32: 5.1.1 | B32: اختبار مخرجات النظام | E32: فحص تقارير النظام | F32: تقارير النظام | G32: تحليل | H32: مخرجات النظام | I32: IAS 1 | J32: IFRS 7 | K32: ISA 330 | L32: سياسة أمن المعلومات | M32: التحقق من موثوقية التقارير | N32: ✔ سجل مقارنة | O32: مقارنة بالتقارير المالية | P32: تقارير غير دقيقة | Q32: عالي | R32: فريق IT | S32: ورقة مقارنة | T32: يوم | U32: توثيق | V32: فقد بيانات | W32: % دقة المخرجات
A33: 5.1.2 | B33: اختبار ضوابط الوصول | E33: فحص المستخدمين | F33: صلاحيات النظام | G33: ملاحظة | H33: قائمة مستخدمين | I33: IAS 1 | J33: IFRS 7 | K33: ISA 330 | L33: سياسة أمن المعلومات | M33: ضمان صلاحيات مناسبة | N33: ✔ سجل وصول | O33: مراجعة الصلاحيات | P33: صلاحيات زائدة | Q33: متوسط | R33: فريق IT | S33: تقرير صلاحيات | T33: يوم | U33: حماية البيانات | V33: تأخير تحديث الصلاحيات | W33: % المستخدمين المحدثين
